Workbook

Sheet Paid and Creators CPT
A1: Channel | B1: Est CPT | C1: Budget PCM | D1: Est Impressions | E1: Est Followers | F1: Cost Per Follow
A2: Creators | B2: 25 | C2: 45000 | D2: =(C2/B2)*1000 -> 1800000 | E2: =D2*0.002 -> 3600 | F2: =C2/E2 -> 12.5
A3: Paid (boost org) | B3: 2.5 | C3: 45000 | D3: =(C3/B3)*1000 -> 18000000 | E3: =D3*0.001 -> 18000 | F3: =C3/E3 -> 2.5
A4: Paid (follower) | B4: 5 | C4: 10000 | D4: =(C4/B4)*1000 -> 2000000 | E4: =D4*0.005 -> 10000 | F4: =C4/E4 -> 1 | H4: followers needed | J4: total imp to deliver followers | K4: impression pm
A5: TOTAL | B5: =SUM(B2:B3)/3 -> 9.1666667 | C5: =SUM(C2:C4) -> 100000 | D5: =SUM(D2:D4) -> 21800000 | E5: =SUM(E2:E4) -> 31600 | F5: =C5/E5 -> 3.164557 | H5: 1500000 | I5: =H5/E5 -> 47.468354 | J5: =D5*I5 -> 1034810127 | K5: =J5/12 -> 86234177
A7: Channel | B7: Est CPV | C7: Budget PCM | D7: Est Views | E7: Est Followers | F7: Cost Per Follow
A8: Creators | B8: 0.03 | C8: 45000 | D8: =C8/B8 -> 1500000 | E8: =D8*0.001 -> 1500 | F8: =C8/E8 -> 30
A9: Paid (paid boost org) | B9: 0.005 | C9: 45000 | D9: =C9/B9 -> 9000000 | E9: =D9*0.000987 -> 8883 | F9: =C9/E9 -> 5.0658561
A10: Paid (follower) | B10: 0.01 | C10: 10000 | D10: =C10/B10 -> 1000000 | E10: =D10*0.01 -> 10000 | F10: =C10/E10 -> 1 | H10: followers needed | J10: total views to deliver followers | K10: views pm
A11: TOTAL | B11: =SUM(B8:B10)/3 -> 0.015 | C11: =sum(C8:C10) -> 100000 | D11: =sum(D8:D10) -> 11500000 | E11: =sum(E8:E10) -> 20383 | F11: =C11/E11 -> 4.9060492 | H11: 1500000 | I11: =H11/E11 -> 73.590737 | J11: =D11*I11 -> 8.4629348e+08 | K11: =J11/12 -> 70524457
B13: based on CPM & spend split as above (45% 45% 10%)
A14: Creators as % of new followers | B14: =E2/E5 -> 0.11392405
A15: Paid boost as % of new followers | B15: =E3/E5 -> 0.56962025
A16: Paid follower growth as % of new followers | B16: =E4/E5 -> 0.3164557

Sheet Growth Chart
B1: March | C1: April | D1: May | E1: June | F1: July | G1: August | H1: September | I1: October | J1: November | K1: December | L1: January | M1: February | N1: March | O1: April | P1: May | Q1: June | R1: July | S1: August | T1: September | U1: October | V1: November | W1: December
A2: Followers (TOTAL) | B2: 1300000 | J2: ='Historical Growth'!C7 -> 1546700 | K2: ='Historical Growth'!C7 -> 1546700 | L2: =K2+($K2/12) -> 1675591.7 | M2: =L2+($K2/12) -> 1804483.3 | N2: =M2+($K2/12) -> 1933375 | O2: =N2+($K2/12) -> 2062266.7 | P2: =O2+($K2/12) -> 2191158.3 | Q2: =P2+($K2/12) -> 2320050 | R2: =Q2+($K2/12) -> 2448941.7 | S2: =R2+($K2/12) -> 2577833.3 | ... W2: =V2+($K2/12) -> 3093400
A3: INSTA | J3: ='Historical Growth'!C5 -> 384000 | K3: ='Historical Growth'!C5 -> 384000 | L3: =K3+($K3/12) -> 416000 | M3: =L3+($K3/12) -> 448000 | N3: =M3+($K3/12) -> 480000 | O3: =N3+($K3/12) -> 512000 | P3: =O3+($K3/12) -> 544000 | Q3: =P3+($K3/12) -> 576000 | R3: =Q3+($K3/12) -> 608000 | S3: =R3+($K3/12) -> 640000 | ... W3: =V3+($K3/12) -> 768000
A4: TT | J4: ='Historical Growth'!C4 -> 572700 | K4: ='Historical Growth'!C4 -> 572700 | L4: =K4+($K4/12) -> 620425 | M4: =L4+($K4/12) -> 668150 | N4: =M4+($K4/12) -> 715875 | O4: =N4+($K4/12) -> 763600 | P4: =O4+($K4/12) -> 811325 | Q4: =P4+($K4/12) -> 859050 | R4: =Q4+($K4/12) -> 906775 | S4: =R4+($K4/12) -> 954500 | ... W4: =V4+($K4/12) -> 1145400
A5: FB | J5: ='Historical Growth'!C6 -> 590000 | K5: ='Historical Growth'!C6 -> 590000 | L5: =K5+($K5/12) -> 639166.67 | M5: =L5+($K5/12) -> 688333.33 | N5: =M5+($K5/12) -> 737500 | O5: =N5+($K5/12) -> 786666.67 | P5: =O5+($K5/12) -> 835833.33 | Q5: =P5+($K5/12) -> 885000 | R5: =Q5+($K5/12) -> 934166.67 | S5: =R5+($K5/12) -> 983333.33 | ... W5: =V5+($K5/12) -> 1180000
A7: % CHANGE PCM | J7: =(J2-$B2)/B2 -> 0.18976923 | K7: =(K2-J2)/J2 -> 0 | L7: =(L2-K2)/K2 -> 0.083333333 | M7: =(M2-L2)/L2 -> 0.076923077 | N7: =(N2-M2)/M2 -> 0.071428571 | O7: =(O2-N2)/N2 -> 0.066666667 | P7: =(P2-O2)/O2 -> 0.0625 | Q7: =(Q2-P2)/P2 -> 0.058823529 | R7: =(R2-Q2)/Q2 -> 0.055555556 | ... W7: =(W2-V2)/V2 -> 0.043478261
A8: FOLLOWER CHANGE PM | K8: =K2-J2 -> 0 | L8: =L2-K2 -> 128891.67 | M8: =M2-L2 -> 128891.67 | N8: =N2-M2 -> 128891.67 | O8: =O2-N2 -> 128891.67 | P8: =P2-O2 -> 128891.67 | Q8: =Q2-P2 -> 128891.67 | R8: =R2-Q2 -> 128891.67 | ... W8: =W2-V2 -> 128891.67
K10: =K2/J2-1 -> 0 | L10: =L2/K2-1 -> 0.083333333 | M10: =M2/L2-1 -> 0.076923077 | N10: =N2/M2-1 -> 0.071428571 | O10: =O2/N2-1 -> 0.066666667 | P10: =P2/O2-1 -> 0.0625 | Q10: =Q2/P2-1 -> 0.058823529 | R10: =R2/Q2-1 -> 0.055555556 | ... W10: =W2/V2-1 -> 0.043478261

Sheet Historical Growth
A1: Follower Count
B2: 45957 | C2: 45987
B3: Month 1 | C3: Month 2 | D3: % Current Growth | E3: % Goal Growth | F3: Goal Target
A4: TT | B4: 563100 | C4: 572700 | D4: =(C4-B4)/B4 -> 0.017048482 | E4: 0.05946 | F4: =C4*2 -> 1145400
A5: IG | B5: 376870 | C5: 384000 | D5: =(C5-B5)/B5 -> 0.018918991 | E5: 0.05946 | F5: =C5*2 -> 768000
A6: FB | C6: 590000 | E6: 0.05946 | F6: =C6*2 -> 1180000 | G6: we don't have an Oct figure for Facebook
A7: Total | C7: =SUM(C4:C6) -> 1546700 | F7: =C7*2 -> 3093400
A9: X | B9: 22800 | C9: 22773 | D9: =(C9-B9)/B9 -> -0.0011842105 | E9: =C9-B9 -> -27
A10: YT | B10: 378000 | C10: 381000 | D10: =(C10-B10)/B10 -> 0.0079365079 | E10: 0.05946 | G10: growth on YT is slower
A14: Historical Growth
B16: 45748 | C16: 45987 | D16: % Growth in 8 months | E16: Compounded MoM Growth since April 1st
A17: TT | B17: 505485 | C17: 572700 | D17: =(C17-B17)/B17 -> 0.1329713 | E17: =(C17/B17)^(1/8)-1 -> 0.015727858
A18: IG | B18: 343394 | C18: 384000 | D18: =(C18-B18)/B18 -> 0.11824901 | E18: =(C18/B18)^(1/8)-1 -> 0.014068553
A19: FB | B19: 544095 | C19: 590000 | D19: =(C19-B19)/B19 -> 0.084369458 | E19: =(C19/B19)^(1/8)-1 -> 0.010176264
A20: YT | B20: 358877 | C20: 381000 | D20: =(C20-B20)/B20 -> 0.061645076 | E20: =(C20/B20)^(1/8)-1 -> 0.007505484
B21: =SUM(B17:B20) -> 1751851 | C21: =SUM(C17:C20) -> 1927700 | E21: =(C21/B21)^(1/8)-1 -> 0.012028599

Sheet Views and Engagements past 8 mo
A1: Social Account Metrics
A2: 8 months April - Nov 2025
B3: Views | C3: Engagement | D3: New Followers
A4: TT | B4: 20521966 | C4: 3413336
A5: FB | B5: 7686087 | C5: 802485 | E5: (views are from vids only)
A6: IG | B6: 16944000 | C6: 2071792 | E6: (can't get views but could scrape them manually for vis but there are lots of statics)
A8: TOTAL | B8: =sum(B4:B7) -> 45152053 | D8: ='Growth Chart'!J2-'Growth Chart'!B2 -> 246700
D9: =D8/B8 -> 0.0054637604
A11: YT | B11: 1050592 | C11: 3451

Sheet Projected Follower Growth
A1: Channel | B1: Historical Growth | C1: Projected Growth | H1: Base
A2: TikTok | B2: 0.0157 | C2: 0.075 | D2: Primary discovery engine | G2: TikTok | H2: 572700
A3: Instagram | B3: 0.0141 | C3: 0.062 | D3: Reels-led scaling + conversion | G3: Instagram | H3: 384000
A4: Facebook | B4: 0.0102 | C4: 0.052 | D4: Share/community growth with support | G4: Facebook | H4: 590000
A5: YouTube | B5: 0.0075 | C5: 0.04 | D5: Steady uplift, lower volatility | G5: YouTube | H5: 381000
H6: =SUM(H2:H5) -> 1927700
B8: 1 | C8: 2 | D8: 3 | E8: 4 | F8: 5 | G8: 6 | H8: 7 | I8: 8 | J8: 9 | K8: 10 | L8: 11 | M8: 12
A9: TikTok | B9: =H2*(1+$C$2) -> 615652.5 | C9: =B9*(1+$C$2) -> 661826.44 | D9: =C9*(1+$C$2) -> 711463.42 | E9: =D9*(1+$C$2) -> 764823.18 | F9: =E9*(1+$C$2) -> 822184.92 | G9: =F9*(1+$C$2) -> 883848.78 | H9: =G9*(1+$C$2) -> 950137.44 | I9: =H9*(1+$C$2) -> 1021397.8 | J9: =I9*(1+$C$2) -> 1098002.6 | ... M9: =L9*(1+$C$2) -> 1364045.2
A10: Instagram | B10: =H3*(1+$C$3) -> 407808 | C10: =B10*(1+$C$3) -> 433092.1 | D10: =C10*(1+$C$3) -> 459943.81 | E10: =D10*(1+$C$3) -> 488460.32 | F10: =E10*(1+$C$3) -> 518744.86 | G10: =F10*(1+$C$3) -> 550907.04 | H10: =G10*(1+$C$3) -> 585063.28 | I10: =H10*(1+$C$3) -> 621337.2 | J10: =I10*(1+$C$3) -> 659860.11 | ... M10: =L10*(1+$C$3) -> 790360.86
A11: Facebook | B11: =H4*(1+$C$4) -> 620680 | C11: =B11*(1+$C$4) -> 652955.36 | D11: =C11*(1+$C$4) -> 686909.04 | E11: =D11*(1+$C$4) -> 722628.31 | F11: =E11*(1+$C$4) -> 760204.98 | G11: =F11*(1+$C$4) -> 799735.64 | H11: =G11*(1+$C$4) -> 841321.89 | I11: =H11*(1+$C$4) -> 885070.63 | J11: =I11*(1+$C$4) -> 931094.3 | ... M11: =L11*(1+$C$4) -> 1084029
A12: YouTube | B12: =H5*(1+$C$5) -> 396240 | C12: =B12*(1+$C$5) -> 412089.6 | D12: =C12*(1+$C$5) -> 428573.18 | E12: =D12*(1+$C$5) -> 445716.11 | F12: =E12*(1+$C$5) -> 463544.76 | G12: =F12*(1+$C$5) -> 482086.55 | H12: =G12*(1+$C$5) -> 501370.01 | I12: =H12*(1+$C$5) -> 521424.81 | J12: =I12*(1+$C$5) -> 542281.8 | ... M12: =L12*(1+$C$5) -> 609993.28
M13: =SUM(M9:M12) -> 3848428.3

Sheet ChatGPT Figures
A1: Platform | B1: Jan | C1: Feb | D1: Mar | E1: Apr | F1: May | G1: Jun | H1: Jul | I1: Aug | J1: Sep | K1: Oct | L1: Nov | M1: Dec
A2: TikTok (TT) | B2: 574K | C2: 621K | D2: 672K | E2: 727K | F2: 787K | G2: 852K | H2: 921K | I2: 997K | J2: 1079K | K2: 1167K | L2: 1263K | M2: 1366K
A3: Instagram (IG) | B3: 385K | C3: 408K | D3: 432K | E3: 458K | F3: 485K | G3: 513K | H3: 544K | I3: 576K | J3: 610K | K3: 646K | L3: 684K | M3: 724K
A4: Facebook (FB) | B4: 593K | C4: 623K | D4: 654K | E4: 687K | F4: 721K | G4: 757K | H4: 795K | I4: 835K | J4: 876K | K4: 920K | L4: 966K | M4: 1015K
A5: YouTube (YT) | B5: 382K | C5: 406K | D5: 432K | E5: 460K | F5: 490K | G5: 521K | H5: 554K | I5: 590K | J5: 627K | K5: 668K | L5: 710K | M5: 756K
A6: TOTAL | B6: 1934K | C6: 2058K | D6: 2190K | E6: 2332K | F6: 2483K | G6: 2643K | H6: 2814K | I6: 2998K | J6: 3192K | K6: 3401K | L6: 3623K | M6: 3861K
A8: Platform | B8: Jan | C8: Feb | D8: Mar | E8: Apr | F8: May | G8: Jun | H8: Jul | I8: Aug | J8: Sep | K8: Oct | L8: Nov | M8: Dec
A9: TikTok (TT) | B9: 574000 | C9: 621000 | D9: 672000 | E9: 727000 | F9: 787000 | G9: 852000 | H9: 921000 | I9: 997000 | J9: 1079000 | K9: 1167000 | L9: 1263000 | M9: 1366000 | N9: =(M9-B9)/B9 -> 1.3797909
A10: Instagram (IG) | B10: 385000 | C10: 408000 | D10: 432000 | E10: 458000 | F10: 485000 | G10: 513000 | H10: 544000 | I10: 576000 | J10: 610000 | K10: 646000 | L10: 684000 | M10: 724000 | N10: =(M10-B10)/B10 -> 0.88051948
A11: Faceboo,000 (FB) | B11: 593000 | C11: 623000 | D11: 654000 | E11: 687000 | F11: 721000 | G11: 757000 | H11: 795000 | I11: 835000 | J11: 876000 | K11: 920000 | L11: 966000 | M11: 1015000 | N11: =(M11-B11)/B11 -> 0.71163575
A12: YouTube (YT) | B12: 382000 | C12: 406000 | D12: 432000 | E12: 460000 | F12: 490000 | G12: 521000 | H12: 554000 | I12: 590000 | J12: 627000 | K12: 668000 | L12: 710000 | M12: 756000 | N12: =(M12-B12)/B12 -> 0.97905759
A13: TOTAL | B13: 1934000 | C13: 2058000 | D13: 2190000 | E13: 2332000 | F13: 2483000 | G13: 2643000 | H13: 2814000 | I13: 2998000 | J13: 3192000 | K13: 3401000 | L13: 3623000 | M13: 3861000 | N13: =(M13-B13)/B13 -> 0.99638056
A15: Platform | B15: 46023 | C15: Feb | D15: Mar | E15: Apr | F15: May | G15: Jun | H15: Jul | I15: Aug | J15: Sep | K15: Oct | L15: Nov | M15: 46357
A16: TOTAL | B16: 1934000 | C16: 2058000 | D16: 2190000 | E16: 2332000 | F16: 2483000 | G16: 2643000 | H16: 2814000 | I16: 2998000 | J16: 3192000 | K16: 3401000 | L16: 3623000 | M16: 3861000

Sheet Competitor Benchmarks
A1: Follower Growth | J1: Reach and Engagement Q3 | R1: IG
S2: Post Volume | U2: Total Views | W2: Total Engagement | Y2: Avg. Engagement | AA2: ER%
B3: Followers* (Apr 2025) | C3: Followers* (Dec 2025) | D3: Net Growth (Apr - Dec 2025) | E3: Follower Growth* (Apr - Dec 2025) | F3: Follower MoM Growth* (Apr - Dec 2025) | L3: Post Volume | M3: Total Views | N3: Total Engagement | O3: Avg. Engagement | P3: ER% | S3: Posts | T3: Reels | U3: Posts | V3: Reels | W3: Posts | X3: Reels | Y3: Posts | Z3: Reels | AA3: Posts | AB3: Reels
A4: Barbie | B4: 20700700 | C4: =C17 -> 21600000 | D4: =C4-B4 -> 899300 | E4: =(C4-B4)/B4 -> 0.043442975 | F4: =(C4/B4)^(1/8)-1 -> 0.0053298784 | J4: Barbie | K4: IG Posts | L4: 15 | M4: 0 | N4: 651576 | O4: =N4/L4 -> 43438.4 | R4: Barbie | S4: =L4 -> 15 | T4: =L5 -> 19 | U4: - | V4: =M5/1000 -> 5665.5 | W4: =N4/1000 -> 651.576 | X4: =N5/1000 -> 198.774 | Y4: =O4/1000 -> 43.4384 | Z4: =O5/1000 -> 10.461789 | AA4: - | AB4: =P5 -> 0.035084988
A5: Strawberry Shortcake | B5: 4600000 | C5: 4880000 | D5: =C5-B5 -> 280000 | E5: =(C5-B5)/B5 -> 0.060869565 | F5: =(C5/B5)^(1/8)-1 -> 0.0074134592 | K5: IG Reels | L5: 19 | M5: 5665500 | N5: 198774 | O5: =N5/L5 -> 10461.789 | P5: =N5/M5 -> 0.035084988 | R5: Strawberry Shortcake | S5: =L16 -> 94 | T5: =L17 -> 54 | U5: - | V5: =M17/1000 -> 13952.6 | W5: =N16/1000 -> 1443.01 | X5: =N17/1000 -> 976.071 | Y5: =O16/1000 -> 15.35117 | Z5: =O17/1000 -> 18.075389 | AA5: - | AB5: =P17 -> 0.069956209
A6: Peanuts (Snoopy) | B6: 20300000 | C6: 21400000 | D6: =C6-B6 -> 1100000 | E6: =(C6-B6)/B6 -> 0.054187192 | F6: =(C6/B6)^(1/8)-1 -> 0.0066180577 | K6: FB Posts | L6: 16 | M6: 0 | N6: 279318 | O6: =N6/L6 -> 17457.375 | R6: Peanuts | S6: =L28 -> 88 | T6: =L29 -> 16 | U6: - | V6: =M29/1000 -> 6676 | W6: =N28/1000 -> 3263.53 | X6: =N29/1000 -> 402.628 | Y6: =O28/1000 -> 37.085568 | Z6: =O29/1000 -> 25.16425 | AA6: - | AB6: =P29 -> 0.060309766
A7: Hello Kitty | B7: 21500000 | C7: 23900000 | D7: =C7-B7 -> 2400000 | E7: =(C7-B7)/B7 -> 0.11162791 | F7: =(C7/B7)^(1/8)-1 -> 0.01331607 | R7: Hello Kitty | S7: =L40 -> 50 | T7: =L41 -> 22 | U7: - | V7: =M41 -> 62000000 | W7: =N40 -> 3601650 | X7: =N41 -> 4102902 | Y7: =O40 -> 72033 | Z7: =O41 -> 186495.55 | AA7: - | AB7: =P41 -> 0.066175839
A8: Squishmallows | B8: 1700000 | C8: 1879000 | D8: =C8-B8 -> 179000 | E8: =(C8-B8)/B8 -> 0.10529412 | F8: =(C8/B8)^(1/8)-1 -> 0.012592561 | K8: FB Reels | L8: 26 | M8: 6110092 | N8: 72904 | O8: =N8/L8 -> 2804 | P8: =N8/M8 -> 0.011931735 | R8: Squishmallows | S8: =L52 -> 29 | T8: =L53 -> 39 | U8: - | V8: =M53 -> 14667000 | W8: =N52 -> 375426 | X8: =N53 -> 542792 | Y8: =O52 -> 12945.724 | Z8: =O53 -> 13917.744 | AA8: - | AB8: =P53 -> 0.037007704
A9: CreativeInc | B9: 1300000 | C9: 1552800 | D9: =C9-B9 -> 252800 | E9: =(C9-B9)/B9 -> 0.19446154 | F9: =(C9/B9)^(1/8)-1 -> 0.022460458 | K9: TT | L9: 23 | M9: 15919600 | N9: 393036 | O9: =N9/L9 -> 17088.522 | P9: =N9/M9 -> 0.024688811 | R9: Care Bears | S9: =L64 -> 71 | T9: =L65 -> 23 | U9: - | V9: =M65 -> 8558600 | W9: =N64 -> 602799 | X9: =N65 -> 372551 | Y9: =O64 -> 8490.1268 | Z9: =O65 -> 16197.87 | AA9: - | AB9: =P65 -> 0.043529432
K10: YT | L10: 107 | M10: 41648589 | N10: 18334 | O10: =N10/L10 -> 171.34579 | P10: =N10/M10 -> 0.00044020699
A11: *IG, TT, FB | K11: YT Shorts | L11: 83 | M11: 4808221 | N11: 57593 | O11: =N11/L11 -> 693.89157 | P11: =N11/M11 -> 0.011978027
K12: Total | L12: =SUM(L4:L11) -> 289 | M12: =SUM(M4:M11) -> 74152002 | N12: =SUM(N4:N11) -> 1671535 | O12: =N12/L12 -> 5783.8581 | R12: YT
A13: Barbie Followers (4 Dec 2025) | K13: Comparison | L13: =L4+L5+L6+L7+L8+L9 -> 99 | N13: =N4+N5+N6+N7+N8+N9 -> 1595608 | O13: =N13/L13 -> 16117.253 | S13: Post Volume | U13: Total Views | W13: Total Engagement | Y13: Avg. Engagement | AA13: ER%
A14: IG | B14: 3.5M | C14: =IFERROR(__xludf.DUMMYFUNCTION("IF(REGEXMATCH(B14, ""K""), SUBSTITUTE(B14, ""K"", """")*1000, IF(REGEXMATCH(B14, ""M""), SUBSTITUTE(B14, ""M"", """")*1000000, (B14*1)))"),3500000.0) -> 3500000 | S14: Videos | T14: Shorts | U14: Videos | V14: Shorts | W14: Videos | X14: Shorts | Y14: Videos | Z14: Shorts | AA14: Videos | AB14: Shorts
A15: FB | B15: 15.8M | C15: =IFERROR(__xludf.DUMMYFUNCTION("IF(REGEXMATCH(B15, ""K""), SUBSTITUTE(B15, ""K"", """")*1000, IF(REGEXMATCH(B15, ""M""), SUBSTITUTE(B15, ""M"", """")*1000000, (B15*1)))"),1.58E7) -> 15800000 | L15: Post Volume | M15: Total Views | N15: Total Engagement | O15: Avg. Engagement | P15: ER% | R15: Barbie | S15: =L10 -> 107 | T15: =L11 -> 83 | U15: =M10 -> 41648589 | V15: =M11 -> 4808221 | W15: =N10 -> 18334 | X15: =N11 -> 57593 | Y15: =O10 -> 171.34579 | Z15: =N11 -> 57593 | AA15: =P10 -> 0.00044020699 | AB15: =P11 -> 0.011978027
A16: TT | B16: 2.3M | C16: =IFERROR(__xludf.DUMMYFUNCTION("IF(REGEXMATCH(B16, ""K""), SUBSTITUTE(B16, ""K"", """")*1000, IF(REGEXMATCH(B16, ""M""), SUBSTITUTE(B16, ""M"", """")*1000000, (B16*1)))"),2300000.0) -> 2300000 | J16: Strawberry Shortcake | K16: IG Posts | L16: 94 | M16: 0 | N16: 1443010 | O16: =N16/L16 -> 15351.17 | R16: Strawberry Shortcake | S16: =L22 -> 90 | T16: - | U16: =M22 -> 8429365 | V16: - | W16: =N22 -> 31688 | X16: - | Y16: =O22 -> 352.08889 | Z16: - | AA16: =P22 -> 0.0037592393 | AB16: -
C17: =SUM(C14:C16) -> 21600000 | K17: IG Reels | L17: 54 | M17: 13952600 | N17: 976071 | O17: =N17/L17 -> 18075.389 | P17: =N17/M17 -> 0.069956209 | R17: Peanuts | S17: =L34 -> 24 | T17: =L35 -> 26 | U17: =M34 -> 4866349 | V17: =M35 -> 1007223 | W17: =N34 -> 10217 | X17: =N35 -> 23634 | Y17: =O34 -> 425.70833 | Z17: =O35 -> 909 | AA17: =P34 -> 0.0020995206 | AB17: =P35 -> 0.023464516
A18: YT | B18: 13.1M | D18: (YT not included in their guidelines data) | K18: FB Posts | L18: 102 | M18: 0 | N18: 165960 | O18: =N18/L18 -> 1627.0588 | R18: Hello Kitty | S18: =L46 -> 30 | T18: =L47 -> 64 | U18: =M46 -> 9656856 | V18: =M47 -> 15644651 | W18: =N46 -> 48958 | X18: =N47 -> 260428 | Y18: =O46 -> 1631.9333 | Z18: =O47 -> 4069.1875 | AA18: =P46 -> 0.005069766 | AB18: =P47 -> 0.016646456
A19: Threads | B19: 0 | D19: (Has a barbie movie account) | R19: Squishmallows | S19: - | T19: - | U19: - | V19: - | W19: - | X19: - | Y19: - | Z19: - | AA19: - | AB19: -
A20: X | B20: 347.3K | D20: (Inactive since 2022) | K20: FB Reels | L20: 53 | M20: 4777552 | N20: 154270 | O20: =N20/L20 -> 2910.7547 | P20: =N20/M20 -> 0.032290596 | R20: Care Bears | S20: =L70 -> 12 | T20: =L71 -> 0 | U20: =M70 -> 456947 | V20: =M71 -> 0 | W20: =N70 -> 1507 | X20: =N71 -> 0 | Y20: =O70 -> 125.58333 | Z20: =O71 -> 0 | AA20: =P70 -> 0.0032979755 | AB20: =P71 -> 0
K21: TT | L21: 42 | M21: 2733518 | N21: 311539 | O21: =N21/L21 -> 7417.5952 | P21: =N21/M21 -> 0.11396998
A22: Strawberry Shortcake Followers (4 Dec 2025) | K22: YT | L22: 90 | M22: 8429365 | N22: 31688 | O22: =N22/L22 -> 352.08889 | P22: =N22/M22 -> 0.0037592393
A23: IG | B23: 875K | C23: =IFERROR(__xludf.DUMMYFUNCTION("IF(REGEXMATCH(B23, ""K""), SUBSTITUTE(B23, ""K"", """")*1000, IF(REGEXMATCH(B23, ""M""), SUBSTITUTE(B23, ""M"", """")*1000000, (B23*1)))"),875000.0) -> 875000 | K23: YT Shorts | L23: 0 | M23: 0 | N23: 0 | O23: 0 | P23: 0
A24: FB | B24: 3.4M | C24: =IFERROR(__xludf.DUMMYFUNCTION("IF(REGEXMATCH(B24, ""K""), SUBSTITUTE(B24, ""K"", """")*1000, IF(REGEXMATCH(B24, ""M""), SUBSTITUTE(B24, ""M"", """")*1000000, (B24*1)))"),3400000.0) -> 3400000 | K24: Total | L24: =SUM(L16:L23) -> 435
A25: TT | B25: 605K | C25: =IFERROR(__xludf.DUMMYFUNCTION("IF(REGEXMATCH(B25, ""K""), SUBSTITUTE(B25, ""K"", """")*1000, IF(REGEXMATCH(B25, ""M""), SUBSTITUTE(B25, ""M"", """")*1000000, (B25*1)))"),605000.0) -> 605000 | K25: Comparison | R25: TT
C26: =SUM(C23:C25) -> 4880000 | S26: Post Volume | T26: Total Views | U26: Total Engagement | V26: Avg. Engagement | W26: ER%
A27: YT | B27: 2.23M | D27: (YT not included in their guidelines data) | L27: Post Volume | M27: Total Views | N27: Total Engagement | O27: Avg. Engagement | P27: ER% | S27: Videos | T27: Videos | U27: Videos | V27: Videos | W27: Videos
A28: Threads | B28: 65.3K | J28: Peanuts | K28: IG Posts | L28: 88 | M28: 0 | N28: 3263530 | O28: =N28/L28 -> 37085.568 | R28: Barbie | S28: =L9 -> 23 | T28: =M9 -> 15919600 | U28: =N9 -> 393036 | V28: =O9 -> 17088.522 | W28: =P9 -> 0.024688811
A29: X | B29: 7606 | D29: (Inactive since 2023) | K29: IG Reels | L29: 16 | M29: 6676000 | N29: 402628 | O29: =N29/L29 -> 25164.25 | P29: =N29/M29 -> 0.060309766 | R29: Strawberry Shortcake | S29: =L21 -> 42 | T29: =M21 -> 2733518 | U29: =N21 -> 311539 | V29: =O21 -> 7417.5952 | W29: =P21 -> 0.11396998
K30: FB Posts | L30: 89 | M30: 0 | N30: 1737696 | O30: =N30/L30 -> 19524.674 | R30: Peanuts | S30: =L33 -> 28 | T30: =M33 -> 11535100 | U30: =N33 -> 1931194 | V30: =O33 -> 68971.214 | W30: =P33 -> 0.16741892
A31: Peanuts Followers (4 Dec 2025) | R31: Hello Kitty | S31: =L45 -> 67 | T31: =M45 -> 33039800 | U31: =N45 -> 3971911 | V31: =O45 -> 59282.254 | W31: =P45 -> 0.12021595
A32: IG | B32: 3.9M | C32: =IFERROR(__xludf.DUMMYFUNCTION("IF(REGEXMATCH(B32, ""K""), SUBSTITUTE(B32, ""K"", """")*1000, IF(REGEXMATCH(B32, ""M""), SUBSTITUTE(B32, ""M"", """")*1000000, (B32*1)))"),3900000.0) -> 3900000 | K32: FB Reels | L32: 12 | M32: 4010013 | N32: 156908 | O32: =N32/L32 -> 13075.667 | P32: =N32/M32 -> 0.03912905 | R32: Squishmallows | S32: =L57 -> 53 | T32: =M57 -> 13488700 | U32: =N57 -> 2048192 | V32: =O57 -> 38645.132 | W32: =P57 -> 0.15184503
A33: FB | B33: 14.2M | C33: =IFERROR(__xludf.DUMMYFUNCTION("IF(REGEXMATCH(B33, ""K""), SUBSTITUTE(B33, ""K"", """")*1000, IF(REGEXMATCH(B33, ""M""), SUBSTITUTE(B33, ""M"", """")*1000000, (B33*1)))"),1.42E7) -> 14200000 | K33: TT | L33: 28 | M33: 11535100 | N33: 1931194 | O33: =N33/L33 -> 68971.214 | P33: =N33/M33 -> 0.16741892 | R33: Care Bears | S33: =L69 -> 113 | T33: =M69 -> 10876271 | U33: =N69 -> 2097204 | V33: =O69 -> 18559.327 | W33: =P69 -> 0.19282381
A34: TT | B34: 3.3M | C34: =IFERROR(__xludf.DUMMYFUNCTION("IF(REGEXMATCH(B34, ""K""), SUBSTITUTE(B34, ""K"", """")*1000, IF(REGEXMATCH(B34, ""M""), SUBSTITUTE(B34, ""M"", """")*1000000, (B34*1)))"),3300000.0) -> 3300000 | K34: YT | L34: 24 | M34: 4866349 | N34: 10217 | O34: =N34/L34 -> 425.70833 | P34: =N34/M34 -> 0.0020995206
C35: =SUM(C32:C34) -> 21400000 | K35: YT Shorts | L35: 26 | M35: 1007223 | N35: 23634 | O35: =N35/L35 -> 909 | P35: =N35/M35 -> 0.023464516
A36: YT | B36: 716K | K36: Total
A37: Threads | B37: 0 | K37: Comparison | R37: FB
A38: X | B38: 1.1M | D38: (Inactive since 2024) | S38: Post Volume | U38: Total Views | W38: Total Engagement | Y38: Avg. Engagement | AA38: ER%
L39: Post Volume | M39: Total Views | N39: Total Engagement | O39: Avg. Engagement | P39: ER% | S39: Static | T39: Reels | U39: Static | V39: Reels | W39: Static | X39: Reels | Y39: Static | Z39: Reels | AA39: Static | AB39: Reels
A40: Hello Kitty Followers (4 Dec 2025) | J40: Hello Kitty | K40: IG Posts | L40: 50 | M40: 0 | N40: 3601650 | O40: =N40/L40 -> 72033 | R40: Barbie | S40: =L6 -> 16 | T40: =L8 -> 26 | U40: - | V40: =M8 -> 6110092 | W40: =N6 -> 279318 | X40: =N8 -> 72904 | Y40: =O6 -> 17457.375 | Z40: =O8 -> 2804 | AA40: - | AB40: =P8 -> 0.011931735
...

Sheet Care Bears Data
A2: Followers | B2: 45627 | C2: 45658 | D2: 45689 | E2: 45717 | F2: 45748 | G2: 45778 | H2: 45809 | I2: 45839 | J2: 45870 | K2: 45901 | L2: 45931 | M2: 45962
A3: YouTube | B3: 324000 | C3: 330000 | D3: 337000 | E3: 343000 | F3: 351000 | G3: 357000 | H3: 362000 | I3: 367000 | J3: 371000 | K3: 373000 | L3: x | M3: 381000
A4: TikTok | B4: 467000 | C4: 471000 | D4: 487000 | E4: 493000 | F4: 502000 | G4: 505000 | H4: 517000 | I4: 536000 | J4: 547000 | K4: 551000 | L4: 567101 | M4: 573461
A5: Instagram | C5: 331168 | D5: 331339 | E5: 343900 | F5: 337492 | G5: 343394 | H5: 345242 | I5: 350290 | J5: 359000 | K5: 368000 | L5: 378746 | M5: 385208
A6: Facebook | C6: 531048 | D6: 533307 | E6: 535471 | F6: 538295 | G6: 543062 | H6: 545309 | I6: 552000 | J6: 559000 | K6: 568000 | L6: 548059 | M6: 592357
A8: # of posts
A9: YouTube | D9: 16 | E9: 14 | F9: 1 | G9: 3 | H9: 8 | I9: 4 | J9: 4 | K9: 3 | L9: x | M9: 4
A10: TikTok | C10: 25 | D10: 34 | E10: 30 | F10: 21 | G10: 26 | H10: 26 | I10: 32 | J10: 36 | K10: 37 | L10: 45 | M10: 37
A11: Instagram | C11: 142 | D11: 159 | E11: 165 | F11: 95 | G11: 138 | H11: 144 | I11: 24 | J11: 33 | K11: 36 | L11: 253 | M11: 37
A12: Facebook | C12: 44 | D12: 67 | E12: 44 | F12: 59 | G12: 51 | H12: 46 | I12: 54 | J12: 68 | K12: 70 | L12: 72 | M12: 67
A14: Engagement %
A15: YouTube | C15: =C21/C27 -> 0.00013393939 | D15: =D21/D27 -> 0.00086052632 | E15: =E21/E27 -> 0.00077061856 | F15: =F21/F27 -> 0.00012560175 | G15: =G21/G27 -> 6.6501241e-05 | H15: =H21/H27 -> 0.00011265432 | I15: =I21/I27 -> #DIV/0! | J15: =J21/J27 -> 0.00010327273 | ... M15: =M21/M27 -> 0.023205742
A16: TikTok | C16: =C22/C28 -> 0.068604651 | D16: =D22/D28 -> 0.14058219 | E16: =E22/E28 -> 0.0578125 | F16: =F22/F28 -> 0.060944206 | G16: =G22/G28 -> 0.030151515 | H16: =H22/H28 -> 0.11130435 | I16: =I22/I28 -> 0.1905972 | J16: =J22/J28 -> 0.070703125 | K16: =K22/K28 -> 0.070440252 | L16: 0.112 | M16: 0.1404
A17: Instagram | C17: 0.092 | D17: 0.1034 | E17: 0.0379 | F17: 0.0529 | G17: 0.0453 | H17: 0.0294 | I17: 0.079 | J17: 0.0633 | K17: 0.054 | L17: 0.1306 | M17: 0.1133
A18: Facebook | C18: 0.0911 | D18: 0.0857 | E18: 0.0945 | F18: 0.0823 | G18: 0.1458 | H18: 0.0764 | I18: 0.0587 | J18: 0.066 | K18: 0.0716 | L18: 0.0703 | M18: 0.0663
A20: Engagement
A21: YouTube (Likes) | C21: 442 | D21: 3270 | E21: 2990 | F21: 574 | G21: 268 | H21: 365 | I21: 236 | J21: 284 | K21: 167 | L21: x | M21: =69+28 -> 97
A22: TikTok | C22: 118000 | D22: 821000 | E22: 111000 | F22: 142000 | G22: 39800 | H22: 384000 | I22: 1500000 | J22: 181000 | K22: 112000 | L22: x | M22: =168315+2444+28577 -> 199336
A23: Instagram | C23: 99900 | D23: 232000 | E23: 148000 | F23: 225000 | G23: 223000 | H23: 150000 | I23: 211000 | J23: 372000 | K23: 371000 | L23: 500802 | M23: 560437
A24: Facebook | C24: 18000 | D24: 61900 | E24: 57300 | F24: 77600 | G24: 107000 | H24: 67400 | I24: 203000 | J24: 241000 | K24: 310000 | L24: x | M24: 281946
A26: Views
A27: YouTube | C27: 3300000 | D27: 3800000 | E27: 3880000 | F27: 4570000 | G27: 4030000 | H27: 3240000 | J27: 2750000 | K27: 1810000 | L27: x | M27: 4180
A28: TikTok | C28: 1720000 | D28: 5840000 | E28: 1920000 | F28: 2330000 | G28: 1320000 | H28: 3450000 | I28: 7870000 | J28: 2560000 | K28: 1590000 | L28: 1882420
A29: Instagram | C29: x | D29: x | E29: x | F29: x | G29: x | H29: x | I29: x | J29: x | K29: 5940000 | L29: x | M29: x
A30: Facebook | C30: x | D30: x | E30: x | F30: x | G30: x | H30: x | I30: x | J30: x | K30: x | L30: 356521 | M30: x
